Started by user [8mha:////4F49ljmtGuJPe9eZyrmYMer1Xyfa2OT5Ref1pEDpNHxyAAAAlx+LCAAAAAAAAP9b85aBtbiIQTGjNKU4P08vOT+vOD8nVc83PyU1x6OyILUoJzMv2y+/JJUBAhiZGBgqihhk0NSjKDWzXb3RdlLBUSYGJk8GtpzUvPSSDB8G5tKinBIGIZ+sxLJE/ZzEvHT94JKizLx0a6BxUmjGOUNodHsLgAzWEgZu/dLi1CL9xJTczDwAj6GcLcAAAAA=[0madmin
Running as SYSTEM
Building in workspace C:\Users\Mayur\PycharmProjects\PythonSelFramework
[PythonSelFramework] $ cmd /c call C:\Users\Mayur\AppData\Local\Temp\jenkins13734924452931486275.bat

C:\Users\Mayur\PycharmProjects\PythonSelFramework>cd tests 

C:\Users\Mayur\PycharmProjects\PythonSelFramework\tests>py.test --browser_name "$browserName"--html=$WORKSPACE\reports\reports.html 
============================= test session starts =============================
platform win32 -- Python 3.11.3, pytest-8.3.3, pluggy-1.5.0
rootdir: C:\Users\Mayur\PycharmProjects\PythonSelFramework\tests
plugins: html-4.1.1, metadata-3.1.1
collected 3 items

test_HomePage.py 
INTERNALERROR> Traceback (most recent call last):
INTERNALERROR>   File "C:\Users\Mayur\AppData\Local\Programs\Python\Python311\Lib\site-packages\_pytest\main.py", line 283, in wrap_session
INTERNALERROR>     session.exitstatus = doit(config, session) or 0
INTERNALERROR>                          ^^^^^^^^^^^^^^^^^^^^^
INTERNALERROR>   File "C:\Users\Mayur\AppData\Local\Programs\Python\Python311\Lib\site-packages\_pytest\main.py", line 337, in _main
INTERNALERROR>     config.hook.pytest_runtestloop(session=session)
INTERNALERROR>   File "C:\Users\Mayur\AppData\Local\Programs\Python\Python311\Lib\site-packages\pluggy\_hooks.py", line 513, in __call__
INTERNALERROR>     return self._hookexec(self.name, self._hookimpls.copy(), kwargs, firstresult)
INTERNALERROR>            ^^^^^^^^^^^^^^^^^^^^^^^^^^^^^^^^^^^^^^^^^^^^^^^^^^^^^^^^^^^^^^^^^^^^^^
INTERNALERROR>   File "C:\Users\Mayur\AppData\Local\Programs\Python\Python311\Lib\site-packages\pluggy\_manager.py", line 120, in _hookexec
INTERNALERROR>     return self._inner_hookexec(hook_name, methods, kwargs, firstresult)
INTERNALERROR>            ^^^^^^^^^^^^^^^^^^^^^^^^^^^^^^^^^^^^^^^^^^^^^^^^^^^^^^^^^^^^^
INTERNALERROR>   File "C:\Users\Mayur\AppData\Local\Programs\Python\Python311\Lib\site-packages\pluggy\_callers.py", line 139, in _multicall
INTERNALERROR>     raise exception.with_traceback(exception.__traceback__)
INTERNALERROR>   File "C:\Users\Mayur\AppData\Local\Programs\Python\Python311\Lib\site-packages\pluggy\_callers.py", line 122, in _multicall
INTERNALERROR>     teardown.throw(exception)  # type: ignore[union-attr]
INTERNALERROR>     ^^^^^^^^^^^^^^^^^^^^^^^^^
INTERNALERROR>   File "C:\Users\Mayur\AppData\Local\Programs\Python\Python311\Lib\site-packages\_pytest\logging.py", line 803, in pytest_runtestloop
INTERNALERROR>     return (yield)  # Run all the tests.
INTERNALERROR>             ^^^^^
INTERNALERROR>   File "C:\Users\Mayur\AppData\Local\Programs\Python\Python311\Lib\site-packages\pluggy\_callers.py", line 122, in _multicall
INTERNALERROR>     teardown.throw(exception)  # type: ignore[union-attr]
INTERNALERROR>     ^^^^^^^^^^^^^^^^^^^^^^^^^
INTERNALERROR>   File "C:\Users\Mayur\AppData\Local\Programs\Python\Python311\Lib\site-packages\_pytest\terminal.py", line 673, in pytest_runtestloop
INTERNALERROR>     result = yield
INTERNALERROR>              ^^^^^
INTERNALERROR>   File "C:\Users\Mayur\AppData\Local\Programs\Python\Python311\Lib\site-packages\pluggy\_callers.py", line 103, in _multicall
INTERNALERROR>     res = hook_impl.function(*args)
INTERNALERROR>           ^^^^^^^^^^^^^^^^^^^^^^^^^
INTERNALERROR>   File "C:\Users\Mayur\AppData\Local\Programs\Python\Python311\Lib\site-packages\_pytest\main.py", line 362, in pytest_runtestloop
INTERNALERROR>     item.config.hook.pytest_runtest_protocol(item=item, nextitem=nextitem)
INTERNALERROR>   File "C:\Users\Mayur\AppData\Local\Programs\Python\Python311\Lib\site-packages\pluggy\_hooks.py", line 513, in __call__
INTERNALERROR>     return self._hookexec(self.name, self._hookimpls.copy(), kwargs, firstresult)
INTERNALERROR>            ^^^^^^^^^^^^^^^^^^^^^^^^^^^^^^^^^^^^^^^^^^^^^^^^^^^^^^^^^^^^^^^^^^^^^^
INTERNALERROR>   File "C:\Users\Mayur\AppData\Local\Programs\Python\Python311\Lib\site-packages\pluggy\_manager.py", line 120, in _hookexec
INTERNALERROR>     return self._inner_hookexec(hook_name, methods, kwargs, firstresult)
INTERNALERROR>            ^^^^^^^^^^^^^^^^^^^^^^^^^^^^^^^^^^^^^^^^^^^^^^^^^^^^^^^^^^^^^
INTERNALERROR>   File "C:\Users\Mayur\AppData\Local\Programs\Python\Python311\Lib\site-packages\pluggy\_callers.py", line 139, in _multicall
INTERNALERROR>     raise exception.with_traceback(exception.__traceback__)
INTERNALERROR>   File "C:\Users\Mayur\AppData\Local\Programs\Python\Python311\Lib\site-packages\pluggy\_callers.py", line 122, in _multicall
INTERNALERROR>     teardown.throw(exception)  # type: ignore[union-attr]
INTERNALERROR>     ^^^^^^^^^^^^^^^^^^^^^^^^^
INTERNALERROR>   File "C:\Users\Mayur\AppData\Local\Programs\Python\Python311\Lib\site-packages\_pytest\warnings.py", line 112, in pytest_runtest_protocol
INTERNALERROR>     return (yield)
INTERNALERROR>             ^^^^^
INTERNALERROR>   File "C:\Users\Mayur\AppData\Local\Programs\Python\Python311\Lib\site-packages\pluggy\_callers.py", line 122, in _multicall
INTERNALERROR>     teardown.throw(exception)  # type: ignore[union-attr]
INTERNALERROR>     ^^^^^^^^^^^^^^^^^^^^^^^^^
INTERNALERROR>   File "C:\Users\Mayur\AppData\Local\Programs\Python\Python311\Lib\site-packages\_pytest\assertion\__init__.py", line 176, in pytest_runtest_protocol
INTERNALERROR>     return (yield)
INTERNALERROR>             ^^^^^
INTERNALERROR>   File "C:\Users\Mayur\AppData\Local\Programs\Python\Python311\Lib\site-packages\pluggy\_callers.py", line 122, in _multicall
INTERNALERROR>     teardown.throw(exception)  # type: ignore[union-attr]
INTERNALERROR>     ^^^^^^^^^^^^^^^^^^^^^^^^^
INTERNALERROR>   File "C:\Users\Mayur\AppData\Local\Programs\Python\Python311\Lib\site-packages\_pytest\unittest.py", line 429, in pytest_runtest_protocol
INTERNALERROR>     res = yield
INTERNALERROR>           ^^^^^
INTERNALERROR>   File "C:\Users\Mayur\AppData\Local\Programs\Python\Python311\Lib\site-packages\pluggy\_callers.py", line 122, in _multicall
INTERNALERROR>     teardown.throw(exception)  # type: ignore[union-attr]
INTERNALERROR>     ^^^^^^^^^^^^^^^^^^^^^^^^^
INTERNALERROR>   File "C:\Users\Mayur\AppData\Local\Programs\Python\Python311\Lib\site-packages\_pytest\faulthandler.py", line 88, in pytest_runtest_protocol
INTERNALERROR>     return (yield)
INTERNALERROR>             ^^^^^
INTERNALERROR>   File "C:\Users\Mayur\AppData\Local\Programs\Python\Python311\Lib\site-packages\pluggy\_callers.py", line 103, in _multicall
INTERNALERROR>     res = hook_impl.function(*args)
INTERNALERROR>           ^^^^^^^^^^^^^^^^^^^^^^^^^
INTERNALERROR>   File "C:\Users\Mayur\AppData\Local\Programs\Python\Python311\Lib\site-packages\_pytest\runner.py", line 113, in pytest_runtest_protocol
INTERNALERROR>     runtestprotocol(item, nextitem=nextitem)
INTERNALERROR>   File "C:\Users\Mayur\AppData\Local\Programs\Python\Python311\Lib\site-packages\_pytest\runner.py", line 126, in runtestprotocol
INTERNALERROR>     rep = call_and_report(item, "setup", log)
INTERNALERROR>           ^^^^^^^^^^^^^^^^^^^^^^^^^^^^^^^^^^^
INTERNALERROR>   File "C:\Users\Mayur\AppData\Local\Programs\Python\Python311\Lib\site-packages\_pytest\runner.py", line 244, in call_and_report
INTERNALERROR>     report: TestReport = ihook.pytest_runtest_makereport(item=item, call=call)
INTERNALERROR>                          ^^^^^^^^^^^^^^^^^^^^^^^^^^^^^^^^^^^^^^^^^^^^^^^^^^^^^
INTERNALERROR>   File "C:\Users\Mayur\AppData\Local\Programs\Python\Python311\Lib\site-packages\pluggy\_hooks.py", line 513, in __call__
INTERNALERROR>     return self._hookexec(self.name, self._hookimpls.copy(), kwargs, firstresult)
INTERNALERROR>            ^^^^^^^^^^^^^^^^^^^^^^^^^^^^^^^^^^^^^^^^^^^^^^^^^^^^^^^^^^^^^^^^^^^^^^
INTERNALERROR>   File "C:\Users\Mayur\AppData\Local\Programs\Python\Python311\Lib\site-packages\pluggy\_manager.py", line 120, in _hookexec
INTERNALERROR>     return self._inner_hookexec(hook_name, methods, kwargs, firstresult)
INTERNALERROR>            ^^^^^^^^^^^^^^^^^^^^^^^^^^^^^^^^^^^^^^^^^^^^^^^^^^^^^^^^^^^^^
INTERNALERROR>   File "C:\Users\Mayur\AppData\Local\Programs\Python\Python311\Lib\site-packages\pluggy\_callers.py", line 156, in _multicall
INTERNALERROR>     teardown[0].send(outcome)
INTERNALERROR>   File "C:\Users\Mayur\PycharmProjects\PythonSelFramework\tests\conftest.py", line 47, in pytest_runtest_makereport
INTERNALERROR>     _capture_screenshot(file_name)
INTERNALERROR>   File "C:\Users\Mayur\PycharmProjects\PythonSelFramework\tests\conftest.py", line 56, in _capture_screenshot
INTERNALERROR>     driver.get_screenshot_as_file(name)
INTERNALERROR>     ^^^^^^^^^^^^^^^^^^^^^^^^^^^^^
INTERNALERROR> AttributeError: 'NoneType' object has no attribute 'get_screenshot_as_file'

============================= 2 warnings in 0.33s =============================

C:\Users\Mayur\PycharmProjects\PythonSelFramework\tests>exit 3 
Build step 'Execute Windows batch command' marked build as failure
Finished: FAILURE
